{"errorMessage": "An error occurred (ModelError) when calling the InvokeEndpoint operation: Received client error (400) from primary with message \"unable to evaluate payload provided\". See https://us-east-1.console.aws.amazon.com/cloudwatch/home?region=us-east-1#logEventViewer:group=/aws/sagemaker/Endpoints/image-classification-2025-08-21-23-57-05-598 in account 135808922609 for more information.", "errorType": "ModelError", "stackTrace": ["  File \"/var/task/lambda_function.py\", line 24, in lambda_handler\n    response = runtime.invoke_endpoint(\n", "  File \"/var/runtime/botocore/client.py\", line 565, in _api_call\n    return self._make_api_call(operation_name, kwargs)\n", "  File \"/var/runtime/botocore/client.py\", line 1021, in _make_api_call\n    raise error_class(parsed_response, operation_name)\n"]}